<?xml version="1.0"?>
<robot xmlns:xacro="http://www.ros.org/wiki/xacro">

    <xacro:include filename='inertial_macros.xacro'/>

    <material name="white">
        <color rgba="1 1 1 1"/>
    </material>

    <material name="orenge">
        <color rgba="1 0.3 0.1 1"/>
    </material>

    <material name="blue">
        <color rgba="0.2 0.2 1 1"/>
    </material>

    <material name="black">
        <color rgba="0 0 0 1"/>
    </material>
    
    
    <link name="base_link">
        
    </link>

    <!-- The base link will sit at the center of the two drive wheels(like the center of the drive rod) -->
    <!-- Here the chassis origin will be the back-bottom-center. ie: behind the drive wheels -->
    <joint name="chassis_joint" type="fixed">
        <parent link="base_link"/>
        <child link="chassis_link"/>
        <!-- The base_link is -0.1 in x to the chassis_link -->
        <origin xyz="-0.1 0.0 0.0"/>        
    </joint>

    <link name="chassis_link">
        <visual>
            <!-- 
                The origin of a box by default is going to be centered around the chassis origin. But we wanted it be be at the back, bottom centered.
                therefore, we need to shift the visuals. So we will have to shift it forward in X half the length & upwards in Z half the height.
                It's like we shift the Box. Not the Orogin.
                 -->
            <origin xyz= "0.15 0 0.075"/>
            <geometry>                
                <box size="0.3 0.3 0.15"/>
            </geometry>
            <material name="white"/>
        </visual>
        <collision>
            <origin xyz= "0.15 0 0.075"/>
            <geometry>                
                <box size="0.3 0.3 0.15"/>
            </geometry>
            <material name="white"/>
        </collision>
        <xacro:inertial_box mass='0.5' x='0.3' y='0.3' z='0.15'>
            <origin xyz="0.15 0.0 0.075" rpy="0.0 0.0 0.0"/>
        </xacro:inertial_box>
        
        <!-- adding a gazebo referebnce to the material/color -->
        <gazebo reference="chassis_link">
            <material>Gazebo/white</material>
        </gazebo>
        
    </link>


    <!-- Left Wheel Link -->
    <joint name="left_wheel_joint" type="continuous">
        <parent link="base_link"/>
        <child link="left_wheel"/>
        <!-- Origin 0.175 away on Y, The origin of a cylinder will default be oriented on Z access. So we roll the cylinder 
        90degrees around the X axix. that is roll. -->
        <origin xyz="0 0.175 0" rpy="-${pi/2} 0.0 0.0"/>
        <!-- axis is rotating around the Z axis. When we have a positive motions on the wheel -->
        <axis xyz="0.0 0.0 1"/>        
    </joint>

    <link name="left_wheel">
        <visual>
            <geometry>
                <cylinder radius="0.05" length="0.04"/>
            </geometry>
            <material name="blue"/>
        </visual>
        <collision>
            <geometry>
                <cylinder radius="0.05" length="0.04"/>
            </geometry>
            <material name="blue"/>
        </collision>
        <xacro:inertial_cylinder mass='0.1' length='0.04' radius='0.05'>
            <origin xyz='0 0 0' rpy='0 0 0'/>
        </xacro:inertial_cylinder>
    </link>
    <!-- adding a gazebo referebnce to the material/color -->
    <gazebo reference="left_wheel">
        <material>Gazebo/Blue</material>
    </gazebo>


    <!-- Right Wheel Link -->
    <joint name="right_wheel_joint" type="continuous">
        <parent link="base_link"/>
        <child link="right_wheel"/>
        <origin xyz="0 -0.175 0" rpy="${pi/2} 0.0 0.0"/>
        <!-- axis is rotating around the -Z axis. When we have a positive motions on the wheel -->
        <axis xyz="0.0 0.0 -1"/>        
    </joint>

    <link name="right_wheel">
        <visual>
            <geometry>
                <cylinder radius="0.05" length="0.04"/>
            </geometry>
            <material name="blue"/>
        </visual>
        <collision>
            <geometry>
                <cylinder radius="0.05" length="0.04"/>
            </geometry>
            <material name="blue"/>
        </collision>
        <xacro:inertial_cylinder mass='0.1' length='0.04' radius='0.05'>
            <origin xyz='0 0 0' rpy='0 0 0'/>
        </xacro:inertial_cylinder>
    </link>
    <!-- adding a gazebo referebnce to the material/color -->
    <gazebo reference="right_wheel">
        <material>Gazebo/Blue</material>
    </gazebo>

    <!-- Caster Wheel -->
    <joint name="caster_wheel_joint" type="fixed">
        <parent link="chassis_link"/>
        <child link="caster_wheel"/>
        <origin xyz="0.24 0 0"/>        
    </joint>

    <link name="caster_wheel">
        <visual>
            <geometry>
                <sphere radius="0.05"/>
            </geometry>
            <material name="black"/>
        </visual>
        <collision>
            <geometry>
                <sphere radius="0.05"/>
            </geometry>
            <material name="black"/>
        </collision>
        <xacro:inertial_sphere mass='0.1' radius='0.05'>
            <origin xyz='0 0 0' rpy='0 0 0'/>
        </xacro:inertial_sphere>
    </link>
    <!-- adding a gazebo referebnce to the material/color -->
    <gazebo reference="caster_wheel">
        <material>Gazebo/Black</material>
        
        <!-- Setting the friction of the caster wheel to a minimum value -->
        <mu1 value="0.0001"/>
        <mu2 value="0.0001"/>

    </gazebo>

</robot>